<?xml version="1.0" ?>
<!-- =================================================================================== -->
<!-- |    This document was autogenerated by xacro from base.xacro                     | -->
<!-- |    EDITING THIS FILE BY HAND IS NOT RECOMMENDED                                 | -->
<!-- =================================================================================== -->
<robot name="zinger">
  <!-- INCLUDES -->
  <material name="black">
    <color rgba="0.01 0.01 0.01 1.000"/>
  </material>
  <material name="silver">
    <color rgba="0.700 0.700 0.700 1.000"/>
  </material>
  <material name="gray">
    <color rgba="0.250 0.250 0.250 1.000"/>
  </material>
  <material name="blue">
    <color rgba="0.000 0.000 0.700 1.000"/>
  </material>
  <material name="orange">
    <color rgba="1.000 0.624 0.000 1.000"/>
  </material>
  <!-- Bump sensor -->
  <!-- Sonar sensor -->
  <!-- IR sensor -->
  <!-- Sensors -->
  <gazebo reference="link_wheel_left_front">
    <mu1>0.9</mu1>
    <mu2>0.9</mu2>
    <kp>500000.0</kp>
    <kd>10.0</kd>
    <minDepth>0.001</minDepth>
    <maxVel>0.1</maxVel>
    <fdir1>1 0 0</fdir1>
    <selfCollide>true</selfCollide>
  </gazebo>
  <gazebo reference="link_wheel_left_rear">
    <mu1>0.9</mu1>
    <mu2>0.9</mu2>
    <kp>500000.0</kp>
    <kd>10.0</kd>
    <minDepth>0.001</minDepth>
    <maxVel>0.1</maxVel>
    <fdir1>1 0 0</fdir1>
    <selfCollide>true</selfCollide>
  </gazebo>
  <gazebo reference="link_wheel_right_rear">
    <mu1>0.9</mu1>
    <mu2>0.9</mu2>
    <kp>500000.0</kp>
    <kd>10.0</kd>
    <minDepth>0.001</minDepth>
    <maxVel>0.1</maxVel>
    <fdir1>1 0 0</fdir1>
    <selfCollide>true</selfCollide>
  </gazebo>
  <gazebo reference="link_wheel_right_front">
    <mu1>0.9</mu1>
    <mu2>0.9</mu2>
    <kp>500000.0</kp>
    <kd>10.0</kd>
    <minDepth>0.001</minDepth>
    <maxVel>0.1</maxVel>
    <fdir1>1 0 0</fdir1>
    <selfCollide>true</selfCollide>
  </gazebo>
  <gazebo reference="link_sensor_imu_imu_center">
    <sensor name="imu_center" type="imu">
      <ignition_frame_id>link_sensor_imu_imu_center</ignition_frame_id>
      <always_on>true</always_on>
      <update_rate>25</update_rate>
      <imu>
        <angular_velocity>
          <x>
            <noise type="gaussian">
              <mean>0.0</mean>
              <stddev>0.0</stddev>
            </noise>
          </x>
          <y>
            <noise type="gaussian">
              <mean>0.0</mean>
              <stddev>0.0</stddev>
            </noise>
          </y>
          <z>
            <noise type="gaussian">
              <mean>0.0</mean>
              <stddev>0.0</stddev>
            </noise>
          </z>
        </angular_velocity>
        <linear_acceleration>
          <x>
            <noise type="gaussian">
              <mean>0.0</mean>
              <stddev>0.0</stddev>
            </noise>
          </x>
          <y>
            <noise type="gaussian">
              <mean>0.0</mean>
              <stddev>0.0</stddev>
            </noise>
          </y>
          <z>
            <noise type="gaussian">
              <mean>0.0</mean>
              <stddev>0.0</stddev>
            </noise>
          </z>
        </linear_acceleration>
      </imu>
      <plugin filename="libignition-gazebo-imu-system.so" name="ignition::gazebo::systems::Imu">
        <alwaysOn>true</alwaysOn>
        <updateRate>25</updateRate>
        <topic>imu</topic>
        <imuName>imu_center</imuName>
      </plugin>
    </sensor>
  </gazebo>
  <gazebo reference="joint_body_to_sensor_imu_imu_center">
    <preserveFixedJoint>true</preserveFixedJoint>
  </gazebo>
  <gazebo reference="link_sensor_lidar_rplidar_front">
    <sensor name="rplidar_front" type="gpu_lidar">
      <!--
                    Move the sensor up slightly from the bottom of the lidar unit.
                -->
      <pose>0 0 0.02 0 0 0</pose>
      <alwaysOn>true</alwaysOn>
      <topic>rplidar_front/scan</topic>
      <update_rate>25</update_rate>
      <lidarName>rplidar_front</lidarName>
      <visualize>true</visualize>
      <ignition_frame_id>link_sensor_lidar_rplidar_front</ignition_frame_id>
      <ray>
        <scan>
          <horizontal>
            <samples>640</samples>
            <resolution>1.0</resolution>
            <min_angle>-3.141592653589793</min_angle>
            <max_angle>3.141592653589793</max_angle>
          </horizontal>
          <vertical>
            <samples>1</samples>
            <resolution>1</resolution>
            <min_angle>0</min_angle>
            <max_angle>0</max_angle>
          </vertical>
        </scan>
        <range>
          <min>0.164</min>
          <max>12.0</max>
          <resolution>0.01</resolution>
        </range>
      </ray>
      <plugin filename="libignition-gazebo-sensors-system.so" name="ignition::gazebo::systems::Sensors">
        <render_engine>ogre2</render_engine>
      </plugin>
    </sensor>
  </gazebo>
  <gazebo reference="joint_body_to_sensor_lidar_rplidar_front">
    <preserveFixedJoint>true</preserveFixedJoint>
  </gazebo>
  <gazebo>
    <plugin filename="ign_ros2_control-system" name="ign_ros2_control::IgnitionROS2ControlPlugin">
      <parameters>/home/cobaltboy/ROS2/Bharat-Forge-Inter-IIT-24/install/zinger_description/share/zinger_description/config/zinger.yaml</parameters>
    </plugin>
  </gazebo>
  <gazebo>
    <plugin filename="libignition-gazebo-pose-publisher-system.so" name="ignition::gazebo::systems::PosePublisher">
      <publish_link_pose>true</publish_link_pose>
      <publish_sensor_pose>true</publish_sensor_pose>
      <publish_collision_pose>false</publish_collision_pose>
      <publish_visual_pose>false</publish_visual_pose>
      <publish_model_pose>true</publish_model_pose>
      <publish_nested_model_pose>true</publish_nested_model_pose>
      <use_pose_vector_msg>true</use_pose_vector_msg>
      <static_publisher>true</static_publisher>
      <static_update_frequency>-1</static_update_frequency>
    </plugin>
  </gazebo>
  <!-- MODEL -->
  <!--
      An empty base footprint that describes the origin of the robot on the ground
    -->
  <link name="base_footprint">
    </link>
  <!--
      An empty base link that describes the origin of the robot at the c.o.g of the chassis
    -->
  <!--
        Define the connection between base_link and base_footprint. Relative to base_link the joint
        is exactly on the ground plane, because ROS considers the joint frame to be the same
        as the child frame.
    -->
  <joint name="joint_base_to_footprint" type="fixed">
    <origin rpy="0 0 0" xyz="0 0 0.07"/>
    <parent link="base_footprint"/>
    <child link="base_link"/>
  </joint>
  <link name="base_link">
    </link>
  <!--
        A box that pretends to be the ground. Used for testing that the scuttle model has been assembled correctly.
    -->
  <!--
    <joint name="joint_ground_to_footprint" type="fixed">
        <origin rpy="0 0 0" xyz="0 0 0"/>
        <parent link="base_footprint"/>
        <child link="ground_for_testing"/>
    </joint>
    <link name="ground_for_testing">
        <visual>
            <geometry>
                <box size="0.5 0.5 0.01"/>
            </geometry>
            <origin rpy="0 0 0" xyz="0.25 -0.25 -0.005"/>
        </visual>
    </link>
    -->
  <!-- The chassis of zinger -->
  <!--
        Define the connection between base_link and chassis_link. Relative to base_link the joint
        is exactly in the c.o.g of the chassis, because ROS considers the joint frame to be the same
        as the child frame.
    -->
  <joint name="chassis_joint" type="fixed">
    <origin rpy="0 0 0" xyz="0.0 0 0.0"/>
    <parent link="base_link"/>
    <child link="chassis_link"/>
  </joint>
  <!--
      The coordinate framework has the X-asis in the direction of forward motion, with the y-axis pointing
      to the left. This is equivalent to the coordinate system defined by the kinematics guide.
    -->
  <link name="chassis_link">
    <inertial>
      <origin rpy="0 0 0" xyz="0 0 0.0"/>
      <mass value="1.0"/>
      <inertia ixx="0.003633333333333334" ixy="0" ixz="0" iyy="0.010508333333333331" iyz="0" izz="0.013541666666666664"/>
    </inertial>
    <visual>
      <origin rpy="0 0 0" xyz="0 0 0.0"/>
      <geometry>
        <box size="0.35 0.2 0.06"/>
      </geometry>
      <material name="orange"/>
    </visual>
    <collision>
      <origin rpy="0 0 0" xyz="0 0 0.0"/>
      <geometry>
        <box size="0.35 0.2 0.06"/>
      </geometry>
    </collision>
  </link>
  <joint name="joint_chassis_to_steering_left_front" type="continuous">
    <origin rpy="0 0 0" xyz="0.12499999999999999 0.15000000000000002 0.024999999999999998"/>
    <parent link="chassis_link"/>
    <child link="link_steering_left_front"/>
    <axis xyz="0.0 0.0 1.0"/>
  </joint>
  <link name="link_steering_left_front">
    <inertial>
      <origin rpy="0 0 0" xyz="0 0 0"/>
      <mass value="0.2"/>
      <inertia ixx="0.0001266666666666667" ixy="0" ixz="0" iyy="0.0001266666666666667" iyz="0" izz="0.00025000000000000006"/>
    </inertial>
    <visual>
      <origin rpy="0 0 0" xyz="0 0 0"/>
      <geometry>
        <cylinder length="0.01" radius="0.05"/>
      </geometry>
      <material name="blue"/>
    </visual>
    <collision>
      <origin rpy="0 0 0" xyz="0 0 0"/>
      <geometry>
        <cylinder length="0.01" radius="0.05"/>
      </geometry>
    </collision>
    <visual>
      <origin rpy="0 0 0" xyz="0 0.04 -0.035"/>
      <geometry>
        <box size="0.04 0.01 0.06"/>
      </geometry>
      <material name="blue"/>
    </visual>
    <collision>
      <origin rpy="0 0 0" xyz="0 0.04 -0.035"/>
      <geometry>
        <box size="0.04 0.01 0.06"/>
      </geometry>
    </collision>
  </link>
  <joint name="joint_steering_to_wheel_left_front" type="continuous">
    <origin rpy="0 0 0" xyz="0 0 -0.055"/>
    <parent link="link_steering_left_front"/>
    <child link="link_wheel_left_front"/>
    <axis xyz="0.0 1.0 0.0"/>
  </joint>
  <link name="link_wheel_left_front">
    <inertial>
      <origin rpy="1.5707963267948966 0 0" xyz="0 0 0"/>
      <mass value="0.2"/>
      <inertia ixx="0.00012166666666666667" ixy="0" ixz="0" iyy="0.00012166666666666667" iyz="0" izz="0.00016"/>
    </inertial>
    <visual>
      <origin rpy="1.5707963267948966 0 0" xyz="0 0 0"/>
      <geometry>
        <cylinder length="0.05" radius="0.04"/>
      </geometry>
      <material name="black"/>
    </visual>
    <collision>
      <origin rpy="1.5707963267948966 0 0" xyz="0 0 0"/>
      <geometry>
        <cylinder length="0.05" radius="0.04"/>
      </geometry>
    </collision>
  </link>
  <joint name="joint_chassis_to_steering_left_rear" type="continuous">
    <origin rpy="0 0 0" xyz="-0.12499999999999999 0.15000000000000002 0.024999999999999998"/>
    <parent link="chassis_link"/>
    <child link="link_steering_left_rear"/>
    <axis xyz="0.0 0.0 1.0"/>
  </joint>
  <link name="link_steering_left_rear">
    <inertial>
      <origin rpy="0 0 0" xyz="0 0 0"/>
      <mass value="0.2"/>
      <inertia ixx="0.0001266666666666667" ixy="0" ixz="0" iyy="0.0001266666666666667" iyz="0" izz="0.00025000000000000006"/>
    </inertial>
    <visual>
      <origin rpy="0 0 0" xyz="0 0 0"/>
      <geometry>
        <cylinder length="0.01" radius="0.05"/>
      </geometry>
      <material name="blue"/>
    </visual>
    <collision>
      <origin rpy="0 0 0" xyz="0 0 0"/>
      <geometry>
        <cylinder length="0.01" radius="0.05"/>
      </geometry>
    </collision>
    <visual>
      <origin rpy="0 0 0" xyz="0 0.04 -0.035"/>
      <geometry>
        <box size="0.04 0.01 0.06"/>
      </geometry>
      <material name="blue"/>
    </visual>
    <collision>
      <origin rpy="0 0 0" xyz="0 0.04 -0.035"/>
      <geometry>
        <box size="0.04 0.01 0.06"/>
      </geometry>
    </collision>
  </link>
  <joint name="joint_steering_to_wheel_left_rear" type="continuous">
    <origin rpy="0 0 0" xyz="0 0 -0.055"/>
    <parent link="link_steering_left_rear"/>
    <child link="link_wheel_left_rear"/>
    <axis xyz="0.0 1.0 0.0"/>
  </joint>
  <link name="link_wheel_left_rear">
    <inertial>
      <origin rpy="1.5707963267948966 0 0" xyz="0 0 0"/>
      <mass value="0.2"/>
      <inertia ixx="0.00012166666666666667" ixy="0" ixz="0" iyy="0.00012166666666666667" iyz="0" izz="0.00016"/>
    </inertial>
    <visual>
      <origin rpy="1.5707963267948966 0 0" xyz="0 0 0"/>
      <geometry>
        <cylinder length="0.05" radius="0.04"/>
      </geometry>
      <material name="black"/>
    </visual>
    <collision>
      <origin rpy="1.5707963267948966 0 0" xyz="0 0 0"/>
      <geometry>
        <cylinder length="0.05" radius="0.04"/>
      </geometry>
    </collision>
  </link>
  <joint name="joint_chassis_to_steering_right_rear" type="continuous">
    <origin rpy="0 0 0" xyz="-0.12499999999999999 -0.15000000000000002 0.024999999999999998"/>
    <parent link="chassis_link"/>
    <child link="link_steering_right_rear"/>
    <axis xyz="0.0 0.0 1.0"/>
  </joint>
  <link name="link_steering_right_rear">
    <inertial>
      <origin rpy="0 0 0" xyz="0 0 0"/>
      <mass value="0.2"/>
      <inertia ixx="0.0001266666666666667" ixy="0" ixz="0" iyy="0.0001266666666666667" iyz="0" izz="0.00025000000000000006"/>
    </inertial>
    <visual>
      <origin rpy="0 0 0" xyz="0 0 0"/>
      <geometry>
        <cylinder length="0.01" radius="0.05"/>
      </geometry>
      <material name="blue"/>
    </visual>
    <collision>
      <origin rpy="0 0 0" xyz="0 0 0"/>
      <geometry>
        <cylinder length="0.01" radius="0.05"/>
      </geometry>
    </collision>
    <visual>
      <origin rpy="0 0 0" xyz="0 -0.04 -0.035"/>
      <geometry>
        <box size="0.04 0.01 0.06"/>
      </geometry>
      <material name="blue"/>
    </visual>
    <collision>
      <origin rpy="0 0 0" xyz="0 -0.04 -0.035"/>
      <geometry>
        <box size="0.04 0.01 0.06"/>
      </geometry>
    </collision>
  </link>
  <joint name="joint_steering_to_wheel_right_rear" type="continuous">
    <origin rpy="0 0 0" xyz="0 0 -0.055"/>
    <parent link="link_steering_right_rear"/>
    <child link="link_wheel_right_rear"/>
    <axis xyz="0.0 1.0 0.0"/>
  </joint>
  <link name="link_wheel_right_rear">
    <inertial>
      <origin rpy="1.5707963267948966 0 0" xyz="0 0 0"/>
      <mass value="0.2"/>
      <inertia ixx="0.00012166666666666667" ixy="0" ixz="0" iyy="0.00012166666666666667" iyz="0" izz="0.00016"/>
    </inertial>
    <visual>
      <origin rpy="1.5707963267948966 0 0" xyz="0 0 0"/>
      <geometry>
        <cylinder length="0.05" radius="0.04"/>
      </geometry>
      <material name="black"/>
    </visual>
    <collision>
      <origin rpy="1.5707963267948966 0 0" xyz="0 0 0"/>
      <geometry>
        <cylinder length="0.05" radius="0.04"/>
      </geometry>
    </collision>
  </link>
  <joint name="joint_chassis_to_steering_right_front" type="continuous">
    <origin rpy="0 0 0" xyz="0.12499999999999999 -0.15000000000000002 0.024999999999999998"/>
    <parent link="chassis_link"/>
    <child link="link_steering_right_front"/>
    <axis xyz="0.0 0.0 1.0"/>
  </joint>
  <link name="link_steering_right_front">
    <inertial>
      <origin rpy="0 0 0" xyz="0 0 0"/>
      <mass value="0.2"/>
      <inertia ixx="0.0001266666666666667" ixy="0" ixz="0" iyy="0.0001266666666666667" iyz="0" izz="0.00025000000000000006"/>
    </inertial>
    <visual>
      <origin rpy="0 0 0" xyz="0 0 0"/>
      <geometry>
        <cylinder length="0.01" radius="0.05"/>
      </geometry>
      <material name="blue"/>
    </visual>
    <collision>
      <origin rpy="0 0 0" xyz="0 0 0"/>
      <geometry>
        <cylinder length="0.01" radius="0.05"/>
      </geometry>
    </collision>
    <visual>
      <origin rpy="0 0 0" xyz="0 -0.04 -0.035"/>
      <geometry>
        <box size="0.04 0.01 0.06"/>
      </geometry>
      <material name="blue"/>
    </visual>
    <collision>
      <origin rpy="0 0 0" xyz="0 -0.04 -0.035"/>
      <geometry>
        <box size="0.04 0.01 0.06"/>
      </geometry>
    </collision>
  </link>
  <joint name="joint_steering_to_wheel_right_front" type="continuous">
    <origin rpy="0 0 0" xyz="0 0 -0.055"/>
    <parent link="link_steering_right_front"/>
    <child link="link_wheel_right_front"/>
    <axis xyz="0.0 1.0 0.0"/>
  </joint>
  <link name="link_wheel_right_front">
    <inertial>
      <origin rpy="1.5707963267948966 0 0" xyz="0 0 0"/>
      <mass value="0.2"/>
      <inertia ixx="0.00012166666666666667" ixy="0" ixz="0" iyy="0.00012166666666666667" iyz="0" izz="0.00016"/>
    </inertial>
    <visual>
      <origin rpy="1.5707963267948966 0 0" xyz="0 0 0"/>
      <geometry>
        <cylinder length="0.05" radius="0.04"/>
      </geometry>
      <material name="black"/>
    </visual>
    <collision>
      <origin rpy="1.5707963267948966 0 0" xyz="0 0 0"/>
      <geometry>
        <cylinder length="0.05" radius="0.04"/>
      </geometry>
    </collision>
  </link>
  <ros2_control name="ZingerJointControl" type="system">
    <hardware>
      <plugin>ign_ros2_control/IgnitionSystem</plugin>
    </hardware>
    <joint name="joint_chassis_to_steering_left_front">
      <command_interface name="position">
        <param name="min">-6.283185307179586</param>
        <param name="max">6.283185307179586</param>
      </command_interface>
      <state_interface name="position"/>
      <state_interface name="velocity"/>
      <state_interface name="acceleration"/>
    </joint>
    <joint name="joint_steering_to_wheel_left_front">
      <command_interface name="velocity">
        <param name="min">-1</param>
        <param name="max">1</param>
      </command_interface>
      <state_interface name="position"/>
      <state_interface name="velocity"/>
      <state_interface name="acceleration"/>
    </joint>
    <joint name="joint_chassis_to_steering_left_rear">
      <command_interface name="position">
        <param name="min">-6.283185307179586</param>
        <param name="max">6.283185307179586</param>
      </command_interface>
      <state_interface name="position"/>
      <state_interface name="velocity"/>
      <state_interface name="acceleration"/>
    </joint>
    <joint name="joint_steering_to_wheel_left_rear">
      <command_interface name="velocity">
        <param name="min">-1</param>
        <param name="max">1</param>
      </command_interface>
      <state_interface name="position"/>
      <state_interface name="velocity"/>
      <state_interface name="acceleration"/>
    </joint>
    <joint name="joint_chassis_to_steering_right_rear">
      <command_interface name="position">
        <param name="min">-6.283185307179586</param>
        <param name="max">6.283185307179586</param>
      </command_interface>
      <state_interface name="position"/>
      <state_interface name="velocity"/>
      <state_interface name="acceleration"/>
    </joint>
    <joint name="joint_steering_to_wheel_right_rear">
      <command_interface name="velocity">
        <param name="min">-1</param>
        <param name="max">1</param>
      </command_interface>
      <state_interface name="position"/>
      <state_interface name="velocity"/>
      <state_interface name="acceleration"/>
    </joint>
    <joint name="joint_chassis_to_steering_right_front">
      <command_interface name="position">
        <param name="min">-6.283185307179586</param>
        <param name="max">6.283185307179586</param>
      </command_interface>
      <state_interface name="position"/>
      <state_interface name="velocity"/>
      <state_interface name="acceleration"/>
    </joint>
    <joint name="joint_steering_to_wheel_right_front">
      <command_interface name="velocity">
        <param name="min">-1</param>
        <param name="max">1</param>
      </command_interface>
      <state_interface name="position"/>
      <state_interface name="velocity"/>
      <state_interface name="acceleration"/>
    </joint>
  </ros2_control>
  <!-- Sensors -->
  <joint name="joint_body_to_sensor_imu_imu_center" type="fixed">
    <origin rpy="0 0 0" xyz="0.0 0.0 0.0"/>
    <parent link="chassis_link"/>
    <child link="link_sensor_imu_imu_center"/>
  </joint>
  <link name="link_sensor_imu_imu_center">
    <visual>
      <origin xyz="0.005 0.005 0.005"/>
      <geometry>
        <box size="0.01 0.01 0.01"/>
      </geometry>
    </visual>
    <collision>
      <origin xyz="0.005 0.005 0.005"/>
      <geometry>
        <box size="0.01 0.01 0.01"/>
      </geometry>
    </collision>
    <inertial>
      <mass value="0.01"/>
      <origin rpy="0 0 0" xyz="0.0 0.0 0.0"/>
      <inertia ixx="1.6666666666666668e-07" ixy="0.0" ixz="0.0" iyy="1.6666666666666668e-07" iyz="0.0" izz="1.6666666666666668e-07"/>
    </inertial>
  </link>
  <joint name="joint_body_to_sensor_lidar_rplidar_front" type="fixed">
    <parent link="chassis_link"/>
    <child link="link_sensor_lidar_rplidar_front"/>
    <origin rpy="0 0 0" xyz="0 0 0.03"/>
  </joint>
  <link name="link_sensor_lidar_rplidar_front">
    <visual>
      <origin rpy="0 0 0" xyz="0.0 0 0.03"/>
      <geometry>
        <box size="0.071 0.1 0.06"/>
      </geometry>
    </visual>
    <collision>
      <origin rpy="0 0 0" xyz="0.0 0 0.03"/>
      <geometry>
        <box size="0.071 0.1 0.06"/>
      </geometry>
    </collision>
    <inertial>
      <mass value="0.17"/>
      <origin rpy="0 0 0" xyz="0.0 0 0.03"/>
      <inertia ixx="0.0001926666666666667" ixy="0.0" ixz="0.0" iyy="0.00012241416666666666" iyz="0.0" izz="0.00021308083333333337"/>
    </inertial>
  </link>
  <!-- Bump -->
  <!-- Sonar -->
  <!-- IR -->
  <!-- Cliff sensors -->
</robot>
